Workbook

Sheet Área
A1: Local | B1: =Dashboard!V6 -> FIBRA | C1: Cabo | D1: Start | E1: Corresp | F1: Tipo | G1: Formação | H1: Tensão | I1: Isolamento | J1: Lances Totais | K1: Lances Realizados | L1: Compr. Prev. | M1: Compr. Real | N1: Compr. Lançado | O1: %Lanç | P1: DE | Q1: PARA | R1: Teste de Continuidade | S1: Born a Born | T1: Megger | U1: Hipot | V1: QTDE Teste | W1: % de Testes Realizados | X1: Terminações | Y1: Ligações | Z1: Disponibilidade
C2: =IF($B$1="Geral",Tabela1[[#This Row],[Tag do Cabo]],IFERROR(INDEX(INDIRECT("BD!$A"&D2&":$A100000"),E2,1),"")) -> 1HVBUS3-ER1HV-001C | D2: 1 | E2: =IFERROR(MATCH($B$1,INDIRECT("BD!$J"&D2&":$J100000"),0),"") -> 4 | F2: =IFERROR(VLOOKUP(Tabela4[[#This Row],[Cabo]],BD!A:V,2,0),"") -> FO | G2: =IFERROR(VLOOKUP(Tabela4[[#This Row],[Cabo]],BD!A:V,5,0),"") -> CORDÃO ÓPTICO | H2: =IFERROR(VLOOKUP(Tabela4[[#This Row],[Cabo]],BD!A:V,3,0),"") -> - | I2: =IFERROR(VLOOKUP(Tabela4[[#This Row],[Cabo]],BD!A:V,4,0),"") -> - | J2: =IFERROR(VLOOKUP(Tabela4[[#This Row],[Cabo]],BD!A:V,7,0),"") -> 1 | K2: =IFERROR(IF(ROUNDDOWN(Tabela4[[#This Row],[%Lanç]]*Tabela4[[#This Row],[Lances Totais]],0)>Tabela4[[#This Row],[Lances Totais]],Tabela4[[#This Row],[Lances Totais]],ROUNDDOWN(Tabela4[[#This Row],[%Lanç]]*Tabela4[[#This Row],[Lances Totais]],0)),"") -> 1 | L2: =IFERROR(VLOOKUP(Tabela4[[#This Row],[Cabo]],BD!A:V,9,0),"") -> 40 | M2: =IFERROR(VLOOKUP(Tabela4[[#This Row],[Cabo]],BD!A:AD,30,0),"") -> 40 | N2: =IF(SUMIF('Lançamento de Cabos'!B:B,Tabela4[[#This Row],[Cabo]],'Lançamento de Cabos'!C:C)=0,"",SUMIF('Lançamento de Cabos'!B:B,Tabela4[[#This Row],[Cabo]],'Lançamento de Cabos'!C:C)) -> 40 | O2: =IFERROR(IF(Tabela4[[#This Row],[Compr. Lançado]]/Tabela4[[#This Row],[Compr. Prev.]]>1,1,Tabela4[[#This Row],[Compr. Lançado]]/Tabela4[[#This Row],[Compr. Prev.]]),"") -> 1 | P2: =IFERROR(VLOOKUP(Tabela4[[#This Row],[Cabo]],BD!A:V,11,0),"") -> 1HV-BUS3 | Q2: =IFERROR(VLOOKUP(Tabela4[[#This Row],[Cabo]],BD!A:V,12,0),"") -> ER-3 | R2: =IF(Tabela4[[#This Row],[Cabo]]<>"",IFERROR(VLOOKUP(Tabela4[[#This Row],[Cabo]]&"-1",'Lançamento de Cabos'!$S:$T,2,0),IF(VLOOKUP(Tabela4[[#This Row],[Cabo]],BD!A:V,13,0)="---","---","")),"") -> --- | S2: =IF(Tabela4[[#This Row],[Cabo]]<>"",IFERROR(VLOOKUP(Tabela4[[#This Row],[Cabo]]&"-2",'Lançamento de Cabos'!$S:$T,2,0),IF(VLOOKUP(Tabela4[[#This Row],[Cabo]],BD!A:V,14,0)="---","---","")),"") -> --- | T2: =IF(Tabela4[[#This Row],[Cabo]]<>"",IFERROR(VLOOKUP(Tabela4[[#This Row],[Cabo]]&"-3",'Lançamento de Cabos'!$S:$T,2,0),IF(VLOOKUP(Tabela4[[#This Row],[Cabo]],BD!A:V,15,0)="---","---","")),"") -> --- | U2: =IF(Tabela4[[#This Row],[Cabo]]<>"",IFERROR(VLOOKUP(Tabela4[[#This Row],[Cabo]]&"-4",'Lançamento de Cabos'!$S:$T,2,0),IF(VLOOKUP(Tabela4[[#This Row],[Cabo]],BD!A:V,16,0)="---","---","")),"") -> --- | V2: =IF(Tabela4[[#This Row],[Cabo]]<>"",4-COUNTIF(Tabela4[[#This Row],[Teste de Continuidade]:[Hipot]],"---"),"") -> 0 | W2: =IF(Tabela4[[#This Row],[Cabo]]<>"",(COUNTIF(Tabela4[[#This Row],[Teste de Continuidade]:[Hipot]],"OK"))/(4-COUNTIF(Tabela4[[#This Row],[Teste de Continuidade]:[Hipot]],"---")),"") -> #DIV/0! | X2: =IF(Tabela4[[#This Row],[Cabo]]<>"",SUMIFS('Lançamento de Cabos'!$AF:$AF,'Lançamento de Cabos'!AE:AE,Tabela4[[#This Row],[Cabo]],'Lançamento de Cabos'!AJ:AJ,Área!$B$1),"") -> 0 | Y2: =IF(Tabela4[[#This Row],[Cabo]]<>"",SUMIFS('Lançamento de Cabos'!$AG:$AG,'Lançamento de Cabos'!AE:AE,Tabela4[[#This Row],[Cabo]],'Lançamento de Cabos'!AJ:AJ,Área!$B$1),"") -> 0 | Z2: =VLOOKUP(Tabela4[[#This Row],[Cabo]],BD!A:AB,28,0) -> Disponível
C3: =IF($B$1="Geral",Tabela1[[#This Row],[Tag do Cabo]],IFERROR(INDEX(INDIRECT("BD!$A"&D3&":$A100000"),E3,1),"")) -> 1HVBUS3-ER1HV-002C | D3: =IFERROR(D2+E2,"") -> 5 | E3: =IFERROR(MATCH($B$1,INDIRECT("BD!$J"&D3&":$J100000"),0),"") -> 1 | F3: =IFERROR(VLOOKUP(Tabela4[[#This Row],[Cabo]],BD!A:V,2,0),"") -> FO | G3: =IFERROR(VLOOKUP(Tabela4[[#This Row],[Cabo]],BD!A:V,5,0),"") -> CORDÃO ÓPTICO | H3: =IFERROR(VLOOKUP(Tabela4[[#This Row],[Cabo]],BD!A:V,3,0),"") -> - | I3: =IFERROR(VLOOKUP(Tabela4[[#This Row],[Cabo]],BD!A:V,4,0),"") -> - | J3: =IFERROR(VLOOKUP(Tabela4[[#This Row],[Cabo]],BD!A:V,7,0),"") -> 1 | K3: =IFERROR(IF(ROUNDDOWN(Tabela4[[#This Row],[%Lanç]]*Tabela4[[#This Row],[Lances Totais]],0)>Tabela4[[#This Row],[Lances Totais]],Tabela4[[#This Row],[Lances Totais]],ROUNDDOWN(Tabela4[[#This Row],[%Lanç]]*Tabela4[[#This Row],[Lances Totais]],0)),"") -> 1 | L3: =IFERROR(VLOOKUP(Tabela4[[#This Row],[Cabo]],BD!A:V,9,0),"") -> 40 | M3: =IFERROR(VLOOKUP(Tabela4[[#This Row],[Cabo]],BD!A:AD,30,0),"") -> 40 | N3: =IF(SUMIF('Lançamento de Cabos'!B:B,Tabela4[[#This Row],[Cabo]],'Lançamento de Cabos'!C:C)=0,"",SUMIF('Lançamento de Cabos'!B:B,Tabela4[[#This Row],[Cabo]],'Lançamento de Cabos'!C:C)) -> 40 | O3: =IFERROR(IF(Tabela4[[#This Row],[Compr. Lançado]]/Tabela4[[#This Row],[Compr. Prev.]]>1,1,Tabela4[[#This Row],[Compr. Lançado]]/Tabela4[[#This Row],[Compr. Prev.]]),"") -> 1 | P3: =IFERROR(VLOOKUP(Tabela4[[#This Row],[Cabo]],BD!A:V,11,0),"") -> 1HV-BUS3 | Q3: =IFERROR(VLOOKUP(Tabela4[[#This Row],[Cabo]],BD!A:V,12,0),"") -> ER-3 | R3: =IF(Tabela4[[#This Row],[Cabo]]<>"",IFERROR(VLOOKUP(Tabela4[[#This Row],[Cabo]]&"-1",'Lançamento de Cabos'!$S:$T,2,0),IF(VLOOKUP(Tabela4[[#This Row],[Cabo]],BD!A:V,13,0)="---","---","")),"") -> --- | S3: =IF(Tabela4[[#This Row],[Cabo]]<>"",IFERROR(VLOOKUP(Tabela4[[#This Row],[Cabo]]&"-2",'Lançamento de Cabos'!$S:$T,2,0),IF(VLOOKUP(Tabela4[[#This Row],[Cabo]],BD!A:V,14,0)="---","---","")),"") -> --- | T3: =IF(Tabela4[[#This Row],[Cabo]]<>"",IFERROR(VLOOKUP(Tabela4[[#This Row],[Cabo]]&"-3",'Lançamento de Cabos'!$S:$T,2,0),IF(VLOOKUP(Tabela4[[#This Row],[Cabo]],BD!A:V,15,0)="---","---","")),"") -> --- | U3: =IF(Tabela4[[#This Row],[Cabo]]<>"",IFERROR(VLOOKUP(Tabela4[[#This Row],[Cabo]]&"-4",'Lançamento de Cabos'!$S:$T,2,0),IF(VLOOKUP(Tabela4[[#This Row],[Cabo]],BD!A:V,16,0)="---","---","")),"") -> --- | V3: =IF(Tabela4[[#This Row],[Cabo]]<>"",4-COUNTIF(Tabela4[[#This Row],[Teste de Continuidade]:[Hipot]],"---"),"") -> 0 | W3: =IF(Tabela4[[#This Row],[Cabo]]<>"",(COUNTIF(Tabela4[[#This Row],[Teste de Continuidade]:[Hipot]],"OK"))/(4-COUNTIF(Tabela4[[#This Row],[Teste de Continuidade]:[Hipot]],"---")),"") -> #DIV/0! | X3: =IF(Tabela4[[#This Row],[Cabo]]<>"",SUMIFS('Lançamento de Cabos'!$AF:$AF,'Lançamento de Cabos'!AE:AE,Tabela4[[#This Row],[Cabo]],'Lançamento de Cabos'!AJ:AJ,Área!$B$1),"") -> 0 | Y3: =IF(Tabela4[[#This Row],[Cabo]]<>"",SUMIFS('Lançamento de Cabos'!$AG:$AG,'Lançamento de Cabos'!AE:AE,Tabela4[[#This Row],[Cabo]],'Lançamento de Cabos'!AJ:AJ,Área!$B$1),"") -> 0 | Z3: =VLOOKUP(Tabela4[[#This Row],[Cabo]],BD!A:AB,28,0) -> Disponível
C4: =IF($B$1="Geral",Tabela1[[#This Row],[Tag do Cabo]],IFERROR(INDEX(INDIRECT("BD!$A"&D4&":$A100000"),E4,1),"")) -> 1HVBUS3-ER1HV-003C | D4: =IFERROR(D3+E3,"") -> 6 | E4: =IFERROR(MATCH($B$1,INDIRECT("BD!$J"&D4&":$J100000"),0),"") -> 1 | F4: =IFERROR(VLOOKUP(Tabela4[[#This Row],[Cabo]],BD!A:V,2,0),"") -> FO | G4: =IFERROR(VLOOKUP(Tabela4[[#This Row],[Cabo]],BD!A:V,5,0),"") -> CORDÃO ÓPTICO | H4: =IFERROR(VLOOKUP(Tabela4[[#This Row],[Cabo]],BD!A:V,3,0),"") -> - | I4: =IFERROR(VLOOKUP(Tabela4[[#This Row],[Cabo]],BD!A:V,4,0),"") -> - | J4: =IFERROR(VLOOKUP(Tabela4[[#This Row],[Cabo]],BD!A:V,7,0),"") -> 1 | K4: =IFERROR(IF(ROUNDDOWN(Tabela4[[#This Row],[%Lanç]]*Tabela4[[#This Row],[Lances Totais]],0)>Tabela4[[#This Row],[Lances Totais]],Tabela4[[#This Row],[Lances Totais]],ROUNDDOWN(Tabela4[[#This Row],[%Lanç]]*Tabela4[[#This Row],[Lances Totais]],0)),"") -> 1 | L4: =IFERROR(VLOOKUP(Tabela4[[#This Row],[Cabo]],BD!A:V,9,0),"") -> 40 | M4: =IFERROR(VLOOKUP(Tabela4[[#This Row],[Cabo]],BD!A:AD,30,0),"") -> 40 | N4: =IF(SUMIF('Lançamento de Cabos'!B:B,Tabela4[[#This Row],[Cabo]],'Lançamento de Cabos'!C:C)=0,"",SUMIF('Lançamento de Cabos'!B:B,Tabela4[[#This Row],[Cabo]],'Lançamento de Cabos'!C:C)) -> 40 | O4: =IFERROR(IF(Tabela4[[#This Row],[Compr. Lançado]]/Tabela4[[#This Row],[Compr. Prev.]]>1,1,Tabela4[[#This Row],[Compr. Lançado]]/Tabela4[[#This Row],[Compr. Prev.]]),"") -> 1 | P4: =IFERROR(VLOOKUP(Tabela4[[#This Row],[Cabo]],BD!A:V,11,0),"") -> 1HV-BUS3 | Q4: =IFERROR(VLOOKUP(Tabela4[[#This Row],[Cabo]],BD!A:V,12,0),"") -> ER-3 | R4: =IF(Tabela4[[#This Row],[Cabo]]<>"",IFERROR(VLOOKUP(Tabela4[[#This Row],[Cabo]]&"-1",'Lançamento de Cabos'!$S:$T,2,0),IF(VLOOKUP(Tabela4[[#This Row],[Cabo]],BD!A:V,13,0)="---","---","")),"") -> --- | S4: =IF(Tabela4[[#This Row],[Cabo]]<>"",IFERROR(VLOOKUP(Tabela4[[#This Row],[Cabo]]&"-2",'Lançamento de Cabos'!$S:$T,2,0),IF(VLOOKUP(Tabela4[[#This Row],[Cabo]],BD!A:V,14,0)="---","---","")),"") -> --- | T4: =IF(Tabela4[[#This Row],[Cabo]]<>"",IFERROR(VLOOKUP(Tabela4[[#This Row],[Cabo]]&"-3",'Lançamento de Cabos'!$S:$T,2,0),IF(VLOOKUP(Tabela4[[#This Row],[Cabo]],BD!A:V,15,0)="---","---","")),"") -> --- | U4: =IF(Tabela4[[#This Row],[Cabo]]<>"",IFERROR(VLOOKUP(Tabela4[[#This Row],[Cabo]]&"-4",'Lançamento de Cabos'!$S:$T,2,0),IF(VLOOKUP(Tabela4[[#This Row],[Cabo]],BD!A:V,16,0)="---","---","")),"") -> --- | V4: =IF(Tabela4[[#This Row],[Cabo]]<>"",4-COUNTIF(Tabela4[[#This Row],[Teste de Continuidade]:[Hipot]],"---"),"") -> 0 | W4: =IF(Tabela4[[#This Row],[Cabo]]<>"",(COUNTIF(Tabela4[[#This Row],[Teste de Continuidade]:[Hipot]],"OK"))/(4-COUNTIF(Tabela4[[#This Row],[Teste de Continuidade]:[Hipot]],"---")),"") -> #DIV/0! | X4: =IF(Tabela4[[#This Row],[Cabo]]<>"",SUMIFS('Lançamento de Cabos'!$AF:$AF,'Lançamento de Cabos'!AE:AE,Tabela4[[#This Row],[Cabo]],'Lançamento de Cabos'!AJ:AJ,Área!$B$1),"") -> 0 | Y4: =IF(Tabela4[[#This Row],[Cabo]]<>"",SUMIFS('Lançamento de Cabos'!$AG:$AG,'Lançamento de Cabos'!AE:AE,Tabela4[[#This Row],[Cabo]],'Lançamento de Cabos'!AJ:AJ,Área!$B$1),"") -> 0 | Z4: =VLOOKUP(Tabela4[[#This Row],[Cabo]],BD!A:AB,28,0) -> Disponível
C5: =IF($B$1="Geral",Tabela1[[#This Row],[Tag do Cabo]],IFERROR(INDEX(INDIRECT("BD!$A"&D5&":$A100000"),E5,1),"")) -> 1HVBUS3-ER1HV-004C | D5: =IFERROR(D4+E4,"") -> 7 | E5: =IFERROR(MATCH($B$1,INDIRECT("BD!$J"&D5&":$J100000"),0),"") -> 1 | F5: =IFERROR(VLOOKUP(Tabela4[[#This Row],[Cabo]],BD!A:V,2,0),"") -> FO | G5: =IFERROR(VLOOKUP(Tabela4[[#This Row],[Cabo]],BD!A:V,5,0),"") -> CORDÃO ÓPTICO | H5: =IFERROR(VLOOKUP(Tabela4[[#This Row],[Cabo]],BD!A:V,3,0),"") -> - | I5: =IFERROR(VLOOKUP(Tabela4[[#This Row],[Cabo]],BD!A:V,4,0),"") -> - | J5: =IFERROR(VLOOKUP(Tabela4[[#This Row],[Cabo]],BD!A:V,7,0),"") -> 1 | K5: =IFERROR(IF(ROUNDDOWN(Tabela4[[#This Row],[%Lanç]]*Tabela4[[#This Row],[Lances Totais]],0)>Tabela4[[#This Row],[Lances Totais]],Tabela4[[#This Row],[Lances Totais]],ROUNDDOWN(Tabela4[[#This Row],[%Lanç]]*Tabela4[[#This Row],[Lances Totais]],0)),"") -> 1 | L5: =IFERROR(VLOOKUP(Tabela4[[#This Row],[Cabo]],BD!A:V,9,0),"") -> 40 | M5: =IFERROR(VLOOKUP(Tabela4[[#This Row],[Cabo]],BD!A:AD,30,0),"") -> 40 | N5: =IF(SUMIF('Lançamento de Cabos'!B:B,Tabela4[[#This Row],[Cabo]],'Lançamento de Cabos'!C:C)=0,"",SUMIF('Lançamento de Cabos'!B:B,Tabela4[[#This Row],[Cabo]],'Lançamento de Cabos'!C:C)) -> 40 | O5: =IFERROR(IF(Tabela4[[#This Row],[Compr. Lançado]]/Tabela4[[#This Row],[Compr. Prev.]]>1,1,Tabela4[[#This Row],[Compr. Lançado]]/Tabela4[[#This Row],[Compr. Prev.]]),"") -> 1 | P5: =IFERROR(VLOOKUP(Tabela4[[#This Row],[Cabo]],BD!A:V,11,0),"") -> 1HV-BUS3 | Q5: =IFERROR(VLOOKUP(Tabela4[[#This Row],[Cabo]],BD!A:V,12,0),"") -> ER-3 | R5: =IF(Tabela4[[#This Row],[Cabo]]<>"",IFERROR(VLOOKUP(Tabela4[[#This Row],[Cabo]]&"-1",'Lançamento de Cabos'!$S:$T,2,0),IF(VLOOKUP(Tabela4[[#This Row],[Cabo]],BD!A:V,13,0)="---","---","")),"") -> --- | S5: =IF(Tabela4[[#This Row],[Cabo]]<>"",IFERROR(VLOOKUP(Tabela4[[#This Row],[Cabo]]&"-2",'Lançamento de Cabos'!$S:$T,2,0),IF(VLOOKUP(Tabela4[[#This Row],[Cabo]],BD!A:V,14,0)="---","---","")),"") -> --- | T5: =IF(Tabela4[[#This Row],[Cabo]]<>"",IFERROR(VLOOKUP(Tabela4[[#This Row],[Cabo]]&"-3",'Lançamento de Cabos'!$S:$T,2,0),IF(VLOOKUP(Tabela4[[#This Row],[Cabo]],BD!A:V,15,0)="---","---","")),"") -> --- | U5: =IF(Tabela4[[#This Row],[Cabo]]<>"",IFERROR(VLOOKUP(Tabela4[[#This Row],[Cabo]]&"-4",'Lançamento de Cabos'!$S:$T,2,0),IF(VLOOKUP(Tabela4[[#This Row],[Cabo]],BD!A:V,16,0)="---","---","")),"") -> --- | V5: =IF(Tabela4[[#This Row],[Cabo]]<>"",4-COUNTIF(Tabela4[[#This Row],[Teste de Continuidade]:[Hipot]],"---"),"") -> 0 | W5: =IF(Tabela4[[#This Row],[Cabo]]<>"",(COUNTIF(Tabela4[[#This Row],[Teste de Continuidade]:[Hipot]],"OK"))/(4-COUNTIF(Tabela4[[#This Row],[Teste de Continuidade]:[Hipot]],"---")),"") -> #DIV/0! | X5: =IF(Tabela4[[#This Row],[Cabo]]<>"",SUMIFS('Lançamento de Cabos'!$AF:$AF,'Lançamento de Cabos'!AE:AE,Tabela4[[#This Row],[Cabo]],'Lançamento de Cabos'!AJ:AJ,Área!$B$1),"") -> 0 | Y5: =IF(Tabela4[[#This Row],[Cabo]]<>"",SUMIFS('Lançamento de Cabos'!$AG:$AG,'Lançamento de Cabos'!AE:AE,Tabela4[[#This Row],[Cabo]],'Lançamento de Cabos'!AJ:AJ,Área!$B$1),"") -> 0 | Z5: =VLOOKUP(Tabela4[[#This Row],[Cabo]],BD!A:AB,28,0) -> Disponível
C6: =IF($B$1="Geral",Tabela1[[#This Row],[Tag do Cabo]],IFERROR(INDEX(INDIRECT("BD!$A"&D6&":$A100000"),E6,1),"")) -> 1HVBUS3-ER1HV-005C | D6: =IFERROR(D5+E5,"") -> 8 | E6: =IFERROR(MATCH($B$1,INDIRECT("BD!$J"&D6&":$J100000"),0),"") -> 1 | F6: =IFERROR(VLOOKUP(Tabela4[[#This Row],[Cabo]],BD!A:V,2,0),"") -> FO | G6: =IFERROR(VLOOKUP(Tabela4[[#This Row],[Cabo]],BD!A:V,5,0),"") -> CORDÃO ÓPTICO | H6: =IFERROR(VLOOKUP(Tabela4[[#This Row],[Cabo]],BD!A:V,3,0),"") -> - | I6: =IFERROR(VLOOKUP(Tabela4[[#This Row],[Cabo]],BD!A:V,4,0),"") -> - | J6: =IFERROR(VLOOKUP(Tabela4[[#This Row],[Cabo]],BD!A:V,7,0),"") -> 1 | K6: =IFERROR(IF(ROUNDDOWN(Tabela4[[#This Row],[%Lanç]]*Tabela4[[#This Row],[Lances Totais]],0)>Tabela4[[#This Row],[Lances Totais]],Tabela4[[#This Row],[Lances Totais]],ROUNDDOWN(Tabela4[[#This Row],[%Lanç]]*Tabela4[[#This Row],[Lances Totais]],0)),"") -> 1 | L6: =IFERROR(VLOOKUP(Tabela4[[#This Row],[Cabo]],BD!A:V,9,0),"") -> 40 | M6: =IFERROR(VLOOKUP(Tabela4[[#This Row],[Cabo]],BD!A:AD,30,0),"") -> 40 | N6: =IF(SUMIF('Lançamento de Cabos'!B:B,Tabela4[[#This Row],[Cabo]],'Lançamento de Cabos'!C:C)=0,"",SUMIF('Lançamento de Cabos'!B:B,Tabela4[[#This Row],[Cabo]],'Lançamento de Cabos'!C:C)) -> 40 | O6: =IFERROR(IF(Tabela4[[#This Row],[Compr. Lançado]]/Tabela4[[#This Row],[Compr. Prev.]]>1,1,Tabela4[[#This Row],[Compr. Lançado]]/Tabela4[[#This Row],[Compr. Prev.]]),"") -> 1 | P6: =IFERROR(VLOOKUP(Tabela4[[#This Row],[Cabo]],BD!A:V,11,0),"") -> 1HV-BUS3 | Q6: =IFERROR(VLOOKUP(Tabela4[[#This Row],[Cabo]],BD!A:V,12,0),"") -> ER-3 | R6: =IF(Tabela4[[#This Row],[Cabo]]<>"",IFERROR(VLOOKUP(Tabela4[[#This Row],[Cabo]]&"-1",'Lançamento de Cabos'!$S:$T,2,0),IF(VLOOKUP(Tabela4[[#This Row],[Cabo]],BD!A:V,13,0)="---","---","")),"") -> --- | S6: =IF(Tabela4[[#This Row],[Cabo]]<>"",IFERROR(VLOOKUP(Tabela4[[#This Row],[Cabo]]&"-2",'Lançamento de Cabos'!$S:$T,2,0),IF(VLOOKUP(Tabela4[[#This Row],[Cabo]],BD!A:V,14,0)="---","---","")),"") -> --- | T6: =IF(Tabela4[[#This Row],[Cabo]]<>"",IFERROR(VLOOKUP(Tabela4[[#This Row],[Cabo]]&"-3",'Lançamento de Cabos'!$S:$T,2,0),IF(VLOOKUP(Tabela4[[#This Row],[Cabo]],BD!A:V,15,0)="---","---","")),"") -> --- | U6: =IF(Tabela4[[#This Row],[Cabo]]<>"",IFERROR(VLOOKUP(Tabela4[[#This Row],[Cabo]]&"-4",'Lançamento de Cabos'!$S:$T,2,0),IF(VLOOKUP(Tabela4[[#This Row],[Cabo]],BD!A:V,16,0)="---","---","")),"") -> --- | V6: =IF(Tabela4[[#This Row],[Cabo]]<>"",4-COUNTIF(Tabela4[[#This Row],[Teste de Continuidade]:[Hipot]],"---"),"") -> 0 | W6: =IF(Tabela4[[#This Row],[Cabo]]<>"",(COUNTIF(Tabela4[[#This Row],[Teste de Continuidade]:[Hipot]],"OK"))/(4-COUNTIF(Tabela4[[#This Row],[Teste de Continuidade]:[Hipot]],"---")),"") -> #DIV/0! | X6: =IF(Tabela4[[#This Row],[Cabo]]<>"",SUMIFS('Lançamento de Cabos'!$AF:$AF,'Lançamento de Cabos'!AE:AE,Tabela4[[#This Row],[Cabo]],'Lançamento de Cabos'!AJ:AJ,Área!$B$1),"") -> 0 | Y6: =IF(Tabela4[[#This Row],[Cabo]]<>"",SUMIFS('Lançamento de Cabos'!$AG:$AG,'Lançamento de Cabos'!AE:AE,Tabela4[[#This Row],[Cabo]],'Lançamento de Cabos'!AJ:AJ,Área!$B$1),"") -> 0 | Z6: =VLOOKUP(Tabela4[[#This Row],[Cabo]],BD!A:AB,28,0) -> Disponível
C7: =IF($B$1="Geral",Tabela1[[#This Row],[Tag do Cabo]],IFERROR(INDEX(INDIRECT("BD!$A"&D7&":$A100000"),E7,1),"")) -> CBO001-SEL | D7: =IFERROR(D6+E6,"") -> 9 | E7: =IFERROR(MATCH($B$1,INDIRECT("BD!$J"&D7&":$J100000"),0),"") -> 12 | F7: =IFERROR(VLOOKUP(Tabela4[[#This Row],[Cabo]],BD!A:V,2,0),"") -> FO | G7: =IFERROR(VLOOKUP(Tabela4[[#This Row],[Cabo]],BD!A:V,5,0),"") -> CORDÃO ÓPTICO | H7: =IFERROR(VLOOKUP(Tabela4[[#This Row],[Cabo]],BD!A:V,3,0),"") -> - | I7: =IFERROR(VLOOKUP(Tabela4[[#This Row],[Cabo]],BD!A:V,4,0),"") -> - | J7: =IFERROR(VLOOKUP(Tabela4[[#This Row],[Cabo]],BD!A:V,7,0),"") -> 1 | K7: =IFERROR(IF(ROUNDDOWN(Tabela4[[#This Row],[%Lanç]]*Tabela4[[#This Row],[Lances Totais]],0)>Tabela4[[#This Row],[Lances Totais]],Tabela4[[#This Row],[Lances Totais]],ROUNDDOWN(Tabela4[[#This Row],[%Lanç]]*Tabela4[[#This Row],[Lances Totais]],0)),"") | L7: =IFERROR(VLOOKUP(Tabela4[[#This Row],[Cabo]],BD!A:V,9,0),"") -> 20 | M7: =IFERROR(VLOOKUP(Tabela4[[#This Row],[Cabo]],BD!A:AD,30,0),"") -> 20 | N7: =IF(SUMIF('Lançamento de Cabos'!B:B,Tabela4[[#This Row],[Cabo]],'Lançamento de Cabos'!C:C)=0,"",SUMIF('Lançamento de Cabos'!B:B,Tabela4[[#This Row],[Cabo]],'Lançamento de Cabos'!C:C)) | O7: =IFERROR(IF(Tabela4[[#This Row],[Compr. Lançado]]/Tabela4[[#This Row],[Compr. Prev.]]>1,1,Tabela4[[#This Row],[Compr. Lançado]]/Tabela4[[#This Row],[Compr. Prev.]]),"") | P7: =IFERROR(VLOOKUP(Tabela4[[#This Row],[Cabo]],BD!A:V,11,0),"") -> ER-3 | Q7: =IFERROR(VLOOKUP(Tabela4[[#This Row],[Cabo]],BD!A:V,12,0),"") -> ER-4 | R7: =IF(Tabela4[[#This Row],[Cabo]]<>"",IFERROR(VLOOKUP(Tabela4[[#This Row],[Cabo]]&"-1",'Lançamento de Cabos'!$S:$T,2,0),IF(VLOOKUP(Tabela4[[#This Row],[Cabo]],BD!A:V,13,0)="---","---","")),"") -> --- | S7: =IF(Tabela4[[#This Row],[Cabo]]<>"",IFERROR(VLOOKUP(Tabela4[[#This Row],[Cabo]]&"-2",'Lançamento de Cabos'!$S:$T,2,0),IF(VLOOKUP(Tabela4[[#This Row],[Cabo]],BD!A:V,14,0)="---","---","")),"") -> --- | T7: =IF(Tabela4[[#This Row],[Cabo]]<>"",IFERROR(VLOOKUP(Tabela4[[#This Row],[Cabo]]&"-3",'Lançamento de Cabos'!$S:$T,2,0),IF(VLOOKUP(Tabela4[[#This Row],[Cabo]],BD!A:V,15,0)="---","---","")),"") -> --- | U7: =IF(Tabela4[[#This Row],[Cabo]]<>"",IFERROR(VLOOKUP(Tabela4[[#This Row],[Cabo]]&"-4",'Lançamento de Cabos'!$S:$T,2,0),IF(VLOOKUP(Tabela4[[#This Row],[Cabo]],BD!A:V,16,0)="---","---","")),"") -> --- | V7: =IF(Tabela4[[#This Row],[Cabo]]<>"",4-COUNTIF(Tabela4[[#This Row],[Teste de Continuidade]:[Hipot]],"---"),"") -> 0 | W7: =IF(Tabela4[[#This Row],[Cabo]]<>"",(COUNTIF(Tabela4[[#This Row],[Teste de Continuidade]:[Hipot]],"OK"))/(4-COUNTIF(Tabela4[[#This Row],[Teste de Continuidade]:[Hipot]],"---")),"") -> #DIV/0! | X7: =IF(Tabela4[[#This Row],[Cabo]]<>"",SUMIFS('Lançamento de Cabos'!$AF:$AF,'Lançamento de Cabos'!AE:AE,Tabela4[[#This Row],[Cabo]],'Lançamento de Cabos'!AJ:AJ,Área!$B$1),"") -> 0 | Y7: =IF(Tabela4[[#This Row],[Cabo]]<>"",SUMIFS('Lançamento de Cabos'!$AG:$AG,'Lançamento de Cabos'!AE:AE,Tabela4[[#This Row],[Cabo]],'Lançamento de Cabos'!AJ:AJ,Área!$B$1),"") -> 0 | Z7: =VLOOKUP(Tabela4[[#This Row],[Cabo]],BD!A:AB,28,0) -> Pend. Compra
C8: =IF($B$1="Geral",Tabela1[[#This Row],[Tag do Cabo]],IFERROR(INDEX(INDIRECT("BD!$A"&D8&":$A100000"),E8,1),"")) -> CDC-02290 | D8: =IFERROR(D7+E7,"") -> 21 | E8: =IFERROR(MATCH($B$1,INDIRECT("BD!$J"&D8&":$J100000"),0),"") -> 38 | F8: =IFERROR(VLOOKUP(Tabela4[[#This Row],[Cabo]],BD!A:V,2,0),"") -> FO | G8: =IFERROR(VLOOKUP(Tabela4[[#This Row],[Cabo]],BD!A:V,5,0),"") -> CORDÃO ÓPTICO | H8: =IFERROR(VLOOKUP(Tabela4[[#This Row],[Cabo]],BD!A:V,3,0),"") -> - | I8: =IFERROR(VLOOKUP(Tabela4[[#This Row],[Cabo]],BD!A:V,4,0),"") -> - | J8: =IFERROR(VLOOKUP(Tabela4[[#This Row],[Cabo]],BD!A:V,7,0),"") -> 1 | K8: =IFERROR(IF(ROUNDDOWN(Tabela4[[#This Row],[%Lanç]]*Tabela4[[#This Row],[Lances Totais]],0)>Tabela4[[#This Row],[Lances Totais]],Tabela4[[#This Row],[Lances Totais]],ROUNDDOWN(Tabela4[[#This Row],[%Lanç]]*Tabela4[[#This Row],[Lances Totais]],0)),"") -> 1 | L8: =IFERROR(VLOOKUP(Tabela4[[#This Row],[Cabo]],BD!A:V,9,0),"") -> 2.5 | M8: =IFERROR(VLOOKUP(Tabela4[[#This Row],[Cabo]],BD!A:AD,30,0),"") -> 2.5 | N8: =IF(SUMIF('Lançamento de Cabos'!B:B,Tabela4[[#This Row],[Cabo]],'Lançamento de Cabos'!C:C)=0,"",SUMIF('Lançamento de Cabos'!B:B,Tabela4[[#This Row],[Cabo]],'Lançamento de Cabos'!C:C)) -> 2.5 | O8: =IFERROR(IF(Tabela4[[#This Row],[Compr. Lançado]]/Tabela4[[#This Row],[Compr. Prev.]]>1,1,Tabela4[[#This Row],[Compr. Lançado]]/Tabela4[[#This Row],[Compr. Prev.]]),"") -> 1 | P8: =IFERROR(VLOOKUP(Tabela4[[#This Row],[Cabo]],BD!A:V,11,0),"") -> DIO-120-104 (30LV) | Q8: =IFERROR(VLOOKUP(Tabela4[[#This Row],[Cabo]],BD!A:V,12,0),"") -> SWT-120-105 (30LV) | R8: =IF(Tabela4[[#This Row],[Cabo]]<>"",IFERROR(VLOOKUP(Tabela4[[#This Row],[Cabo]]&"-1",'Lançamento de Cabos'!$S:$T,2,0),IF(VLOOKUP(Tabela4[[#This Row],[Cabo]],BD!A:V,13,0)="---","---","")),"") -> --- | S8: =IF(Tabela4[[#This Row],[Cabo]]<>"",IFERROR(VLOOKUP(Tabela4[[#This Row],[Cabo]]&"-2",'Lançamento de Cabos'!$S:$T,2,0),IF(VLOOKUP(Tabela4[[#This Row],[Cabo]],BD!A:V,14,0)="---","---","")),"") -> --- | T8: =IF(Tabela4[[#This Row],[Cabo]]<>"",IFERROR(VLOOKUP(Tabela4[[#This Row],[Cabo]]&"-3",'Lançamento de Cabos'!$S:$T,2,0),IF(VLOOKUP(Tabela4[[#This Row],[Cabo]],BD!A:V,15,0)="---","---","")),"") -> --- | U8: =IF(Tabela4[[#This Row],[Cabo]]<>"",IFERROR(VLOOKUP(Tabela4[[#This Row],[Cabo]]&"-4",'Lançamento de Cabos'!$S:$T,2,0),IF(VLOOKUP(Tabela4[[#This Row],[Cabo]],BD!A:V,16,0)="---","---","")),"") -> --- | V8: =IF(Tabela4[[#This Row],[Cabo]]<>"",4-COUNTIF(Tabela4[[#This Row],[Teste de Continuidade]:[Hipot]],"---"),"") -> 0 | W8: =IF(Tabela4[[#This Row],[Cabo]]<>"",(COUNTIF(Tabela4[[#This Row],[Teste de Continuidade]:[Hipot]],"OK"))/(4-COUNTIF(Tabela4[[#This Row],[Teste de Continuidade]:[Hipot]],"---")),"") -> #DIV/0! | X8: =IF(Tabela4[[#This Row],[Cabo]]<>"",SUMIFS('Lançamento de Cabos'!$AF:$AF,'Lançamento de Cabos'!AE:AE,Tabela4[[#This Row],[Cabo]],'Lançamento de Cabos'!AJ:AJ,Área!$B$1),"") -> 0 | Y8: =IF(Tabela4[[#This Row],[Cabo]]<>"",SUMIFS('Lançamento de Cabos'!$AG:$AG,'Lançamento de Cabos'!AE:AE,Tabela4[[#This Row],[Cabo]],'Lançamento de Cabos'!AJ:AJ,Área!$B$1),"") -> 0 | Z8: =VLOOKUP(Tabela4[[#This Row],[Cabo]],BD!A:AB,28,0) -> Disponível
C9: =IF($B$1="Geral",Tabela1[[#This Row],[Tag do Cabo]],IFERROR(INDEX(INDIRECT("BD!$A"&D9&":$A100000"),E9,1),"")) -> CDC-02331 | D9: =IFERROR(D8+E8,"") -> 59 | E9: =IFERROR(MATCH($B$1,INDIRECT("BD!$J"&D9&":$J100000"),0),"") -> 1 | F9: =IFERROR(VLOOKUP(Tabela4[[#This Row],[Cabo]],BD!A:V,2,0),"") -> FO | G9: =IFERROR(VLOOKUP(Tabela4[[#This Row],[Cabo]],BD!A:V,5,0),"") -> CORDÃO ÓPTICO | H9: =IFERROR(VLOOKUP(Tabela4[[#This Row],[Cabo]],BD!A:V,3,0),"") -> - | I9: =IFERROR(VLOOKUP(Tabela4[[#This Row],[Cabo]],BD!A:V,4,0),"") -> - | J9: =IFERROR(VLOOKUP(Tabela4[[#This Row],[Cabo]],BD!A:V,7,0),"") -> 1 | K9: =IFERROR(IF(ROUNDDOWN(Tabela4[[#This Row],[%Lanç]]*Tabela4[[#This Row],[Lances Totais]],0)>Tabela4[[#This Row],[Lances Totais]],Tabela4[[#This Row],[Lances Totais]],ROUNDDOWN(Tabela4[[#This Row],[%Lanç]]*Tabela4[[#This Row],[Lances Totais]],0)),"") -> 1 | L9: =IFERROR(VLOOKUP(Tabela4[[#This Row],[Cabo]],BD!A:V,9,0),"") -> 5 | M9: =IFERROR(VLOOKUP(Tabela4[[#This Row],[Cabo]],BD!A:AD,30,0),"") -> 5 | N9: =IF(SUMIF('Lançamento de Cabos'!B:B,Tabela4[[#This Row],[Cabo]],'Lançamento de Cabos'!C:C)=0,"",SUMIF('Lançamento de Cabos'!B:B,Tabela4[[#This Row],[Cabo]],'Lançamento de Cabos'!C:C)) -> 5 | O9: =IFERROR(IF(Tabela4[[#This Row],[Compr. Lançado]]/Tabela4[[#This Row],[Compr. Prev.]]>1,1,Tabela4[[#This Row],[Compr. Lançado]]/Tabela4[[#This Row],[Compr. Prev.]]),"") -> 1 | P9: =IFERROR(VLOOKUP(Tabela4[[#This Row],[Cabo]],BD!A:V,11,0),"") -> PI-1205 (ACESSO REMOTO) | Q9: =IFERROR(VLOOKUP(Tabela4[[#This Row],[Cabo]],BD!A:V,12,0),"") -> SWT-120-105 (30LV) | R9: =IF(Tabela4[[#This Row],[Cabo]]<>"",IFERROR(VLOOKUP(Tabela4[[#This Row],[Cabo]]&"-1",'Lançamento de Cabos'!$S:$T,2,0),IF(VLOOKUP(Tabela4[[#This Row],[Cabo]],BD!A:V,13,0)="---","---","")),"") -> --- | S9: =IF(Tabela4[[#This Row],[Cabo]]<>"",IFERROR(VLOOKUP(Tabela4[[#This Row],[Cabo]]&"-2",'Lançamento de Cabos'!$S:$T,2,0),IF(VLOOKUP(Tabela4[[#This Row],[Cabo]],BD!A:V,14,0)="---","---","")),"") -> --- | T9: =IF(Tabela4[[#This Row],[Cabo]]<>"",IFERROR(VLOOKUP(Tabela4[[#This Row],[Cabo]]&"-3",'Lançamento de Cabos'!$S:$T,2,0),IF(VLOOKUP(Tabela4[[#This Row],[Cabo]],BD!A:V,15,0)="---","---","")),"") -> --- | U9: =IF(Tabela4[[#This Row],[Cabo]]<>"",IFERROR(VLOOKUP(Tabela4[[#This Row],[Cabo]]&"-4",'Lançamento de Cabos'!$S:$T,2,0),IF(VLOOKUP(Tabela4[[#This Row],[Cabo]],BD!A:V,16,0)="---","---","")),"") -> --- | V9: =IF(Tabela4[[#This Row],[Cabo]]<>"",4-COUNTIF(Tabela4[[#This Row],[Teste de Continuidade]:[Hipot]],"---"),"") -> 0 | W9: =IF(Tabela4[[#This Row],[Cabo]]<>"",(COUNTIF(Tabela4[[#This Row],[Teste de Continuidade]:[Hipot]],"OK"))/(4-COUNTIF(Tabela4[[#This Row],[Teste de Continuidade]:[Hipot]],"---")),"") -> #DIV/0! | X9: =IF(Tabela4[[#This Row],[Cabo]]<>"",SUMIFS('Lançamento de Cabos'!$AF:$AF,'Lançamento de Cabos'!AE:AE,Tabela4[[#This Row],[Cabo]],'Lançamento de Cabos'!AJ:AJ,Área!$B$1),"") -> 0 | Y9: =IF(Tabela4[[#This Row],[Cabo]]<>"",SUMIFS('Lançamento de Cabos'!$AG:$AG,'Lançamento de Cabos'!AE:AE,Tabela4[[#This Row],[Cabo]],'Lançamento de Cabos'!AJ:AJ,Área!$B$1),"") -> 0 | Z9: =VLOOKUP(Tabela4[[#This Row],[Cabo]],BD!A:AB,28,0) -> Disponível
C10: =IF($B$1="Geral",Tabela1[[#This Row],[Tag do Cabo]],IFERROR(INDEX(INDIRECT("BD!$A"&D10&":$A100000"),E10,1),"")) -> 7HV-1HV-001C | D10: =IFERROR(D9+E9,"") -> 60 | E10: =IFERROR(MATCH($B$1,INDIRECT("BD!$J"&D10&":$J100000"),0),"") -> 112 | F10: =IFERROR(VLOOKUP(Tabela4[[#This Row],[Cabo]],BD!A:V,2,0),"") -> FO | G10: =IFERROR(VLOOKUP(Tabela4[[#This Row],[Cabo]],BD!A:V,5,0),"") -> CABO ÓPTICO 4 VIAS | H10: =IFERROR(VLOOKUP(Tabela4[[#This Row],[Cabo]],BD!A:V,3,0),"") -> - | I10: =IFERROR(VLOOKUP(Tabela4[[#This Row],[Cabo]],BD!A:V,4,0),"") -> - | J10: =IFERROR(VLOOKUP(Tabela4[[#This Row],[Cabo]],BD!A:V,7,0),"") -> 1 | K10: =IFERROR(IF(ROUNDDOWN(Tabela4[[#This Row],[%Lanç]]*Tabela4[[#This Row],[Lances Totais]],0)>Tabela4[[#This Row],[Lances Totais]],Tabela4[[#This Row],[Lances Totais]],ROUNDDOWN(Tabela4[[#This Row],[%Lanç]]*Tabela4[[#This Row],[Lances Totais]],0)),"") -> 1 | L10: =IFERROR(VLOOKUP(Tabela4[[#This Row],[Cabo]],BD!A:V,9,0),"") -> 450 | M10: =IFERROR(VLOOKUP(Tabela4[[#This Row],[Cabo]],BD!A:AD,30,0),"") -> 450 | N10: =IF(SUMIF('Lançamento de Cabos'!B:B,Tabela4[[#This Row],[Cabo]],'Lançamento de Cabos'!C:C)=0,"",SUMIF('Lançamento de Cabos'!B:B,Tabela4[[#This Row],[Cabo]],'Lançamento de Cabos'!C:C)) -> 450 | O10: =IFERROR(IF(Tabela4[[#This Row],[Compr. Lançado]]/Tabela4[[#This Row],[Compr. Prev.]]>1,1,Tabela4[[#This Row],[Compr. Lançado]]/Tabela4[[#This Row],[Compr. Prev.]]),"") -> 1 | P10: =IFERROR(VLOOKUP(Tabela4[[#This Row],[Cabo]],BD!A:V,11,0),"") -> 7HV | Q10: =IFERROR(VLOOKUP(Tabela4[[#This Row],[Cabo]],BD!A:V,12,0),"") -> REMOTA 1HV | R10: =IF(Tabela4[[#This Row],[Cabo]]<>"",IFERROR(VLOOKUP(Tabela4[[#This Row],[Cabo]]&"-1",'Lançamento de Cabos'!$S:$T,2,0),IF(VLOOKUP(Tabela4[[#This Row],[Cabo]],BD!A:V,13,0)="---","---","")),"") -> --- | S10: =IF(Tabela4[[#This Row],[Cabo]]<>"",IFERROR(VLOOKUP(Tabela4[[#This Row],[Cabo]]&"-2",'Lançamento de Cabos'!$S:$T,2,0),IF(VLOOKUP(Tabela4[[#This Row],[Cabo]],BD!A:V,14,0)="---","---","")),"") -> --- | T10: =IF(Tabela4[[#This Row],[Cabo]]<>"",IFERROR(VLOOKUP(Tabela4[[#This Row],[Cabo]]&"-3",'Lançamento de Cabos'!$S:$T,2,0),IF(VLOOKUP(Tabela4[[#This Row],[Cabo]],BD!A:V,15,0)="---","---","")),"") -> --- | U10: =IF(Tabela4[[#This Row],[Cabo]]<>"",IFERROR(VLOOKUP(Tabela4[[#This Row],[Cabo]]&"-4",'Lançamento de Cabos'!$S:$T,2,0),IF(VLOOKUP(Tabela4[[#This Row],[Cabo]],BD!A:V,16,0)="---","---","")),"") -> --- | V10: =IF(Tabela4[[#This Row],[Cabo]]<>"",4-COUNTIF(Tabela4[[#This Row],[Teste de Continuidade]:[Hipot]],"---"),"") -> 0 | W10: =IF(Tabela4[[#This Row],[Cabo]]<>"",(COUNTIF(Tabela4[[#This Row],[Teste de Continuidade]:[Hipot]],"OK"))/(4-COUNTIF(Tabela4[[#This Row],[Teste de Continuidade]:[Hipot]],"---")),"") -> #DIV/0! | X10: =IF(Tabela4[[#This Row],[Cabo]]<>"",SUMIFS('Lançamento de Cabos'!$AF:$AF,'Lançamento de Cabos'!AE:AE,Tabela4[[#This Row],[Cabo]],'Lançamento de Cabos'!AJ:AJ,Área!$B$1),"") -> 0 | Y10: =IF(Tabela4[[#This Row],[Cabo]]<>"",SUMIFS('Lançamento de Cabos'!$AG:$AG,'Lançamento de Cabos'!AE:AE,Tabela4[[#This Row],[Cabo]],'Lançamento de Cabos'!AJ:AJ,Área!$B$1),"") -> 0 | Z10: =VLOOKUP(Tabela4[[#This Row],[Cabo]],BD!A:AB,28,0) -> Disponível
C11: =IF($B$1="Geral",Tabela1[[#This Row],[Tag do Cabo]],IFERROR(INDEX(INDIRECT("BD!$A"&D11&":$A100000"),E11,1),"")) -> CBO005-RS | D11: =IFERROR(D10+E10,"") -> 172 | E11: =IFERROR(MATCH($B$1,INDIRECT("BD!$J"&D11&":$J100000"),0),"") -> 1 | F11: =IFERROR(VLOOKUP(Tabela4[[#This Row],[Cabo]],BD!A:V,2,0),"") -> FO | G11: =IFERROR(VLOOKUP(Tabela4[[#This Row],[Cabo]],BD!A:V,5,0),"") -> CABO ÓPTICO 4 VIAS | H11: =IFERROR(VLOOKUP(Tabela4[[#This Row],[Cabo]],BD!A:V,3,0),"") -> - | I11: =IFERROR(VLOOKUP(Tabela4[[#This Row],[Cabo]],BD!A:V,4,0),"") -> - | J11: =IFERROR(VLOOKUP(Tabela4[[#This Row],[Cabo]],BD!A:V,7,0),"") -> 1 | K11: =IFERROR(IF(ROUNDDOWN(Tabela4[[#This Row],[%Lanç]]*Tabela4[[#This Row],[Lances Totais]],0)>Tabela4[[#This Row],[Lances Totais]],Tabela4[[#This Row],[Lances Totais]],ROUNDDOWN(Tabela4[[#This Row],[%Lanç]]*Tabela4[[#This Row],[Lances Totais]],0)),"") -> 1 | L11: =IFERROR(VLOOKUP(Tabela4[[#This Row],[Cabo]],BD!A:V,9,0),"") -> 450 | M11: =IFERROR(VLOOKUP(Tabela4[[#This Row],[Cabo]],BD!A:AD,30,0),"") -> 450 | N11: =IF(SUMIF('Lançamento de Cabos'!B:B,Tabela4[[#This Row],[Cabo]],'Lançamento de Cabos'!C:C)=0,"",SUMIF('Lançamento de Cabos'!B:B,Tabela4[[#This Row],[Cabo]],'Lançamento de Cabos'!C:C)) -> 450 | O11: =IFERROR(IF(Tabela4[[#This Row],[Compr. Lançado]]/Tabela4[[#This Row],[Compr. Prev.]]>1,1,Tabela4[[#This Row],[Compr. Lançado]]/Tabela4[[#This Row],[Compr. Prev.]]),"") -> 1 | P11: =IFERROR(VLOOKUP(Tabela4[[#This Row],[Cabo]],BD!A:V,11,0),"") -> PSDC2-DIO | Q11: =IFERROR(VLOOKUP(Tabela4[[#This Row],[Cabo]],BD!A:V,12,0),"") -> PSDC4-DIO1 | R11: =IF(Tabela4[[#This Row],[Cabo]]<>"",IFERROR(VLOOKUP(Tabela4[[#This Row],[Cabo]]&"-1",'Lançamento de Cabos'!$S:$T,2,0),IF(VLOOKUP(Tabela4[[#This Row],[Cabo]],BD!A:V,13,0)="---","---","")),"") -> --- | S11: =IF(Tabela4[[#This Row],[Cabo]]<>"",IFERROR(VLOOKUP(Tabela4[[#This Row],[Cabo]]&"-2",'Lançamento de Cabos'!$S:$T,2,0),IF(VLOOKUP(Tabela4[[#This Row],[Cabo]],BD!A:V,14,0)="---","---","")),"") -> --- | T11: =IF(Tabela4[[#This Row],[Cabo]]<>"",IFERROR(VLOOKUP(Tabela4[[#This Row],[Cabo]]&"-3",'Lançamento de Cabos'!$S:$T,2,0),IF(VLOOKUP(Tabela4[[#This Row],[Cabo]],BD!A:V,15,0)="---","---","")),"") -> --- | U11: =IF(Tabela4[[#This Row],[Cabo]]<>"",IFERROR(VLOOKUP(Tabela4[[#This Row],[Cabo]]&"-4",'Lançamento de Cabos'!$S:$T,2,0),IF(VLOOKUP(Tabela4[[#This Row],[Cabo]],BD!A:V,16,0)="---","---","")),"") -> --- | V11: =IF(Tabela4[[#This Row],[Cabo]]<>"",4-COUNTIF(Tabela4[[#This Row],[Teste de Continuidade]:[Hipot]],"---"),"") -> 0 | W11: =IF(Tabela4[[#This Row],[Cabo]]<>"",(COUNTIF(Tabela4[[#This Row],[Teste de Continuidade]:[Hipot]],"OK"))/(4-COUNTIF(Tabela4[[#This Row],[Teste de Continuidade]:[Hipot]],"---")),"") -> #DIV/0! | X11: =IF(Tabela4[[#This Row],[Cabo]]<>"",SUMIFS('Lançamento de Cabos'!$AF:$AF,'Lançamento de Cabos'!AE:AE,Tabela4[[#This Row],[Cabo]],'Lançamento de Cabos'!AJ:AJ,Área!$B$1),"") -> 0 | Y11: =IF(Tabela4[[#This Row],[Cabo]]<>"",SUMIFS('Lançamento de Cabos'!$AG:$AG,'Lançamento de Cabos'!AE:AE,Tabela4[[#This Row],[Cabo]],'Lançamento de Cabos'!AJ:AJ,Área!$B$1),"") -> 8 | Z11: =VLOOKUP(Tabela4[[#This Row],[Cabo]],BD!A:AB,28,0) -> Disponível
C12: =IF($B$1="Geral",Tabela1[[#This Row],[Tag do Cabo]],IFERROR(INDEX(INDIRECT("BD!$A"&D12&":$A100000"),E12,1),"")) -> CDC-12009 | D12: =IFERROR(D11+E11,"") -> 173 | E12: =IFERROR(MATCH($B$1,INDIRECT("BD!$J"&D12&":$J100000"),0),"") -> 2 | F12: =IFERROR(VLOOKUP(Tabela4[[#This Row],[Cabo]],BD!A:V,2,0),"") -> FO | G12: =IFERROR(VLOOKUP(Tabela4[[#This Row],[Cabo]],BD!A:V,5,0),"") -> FIBRA OPTICA SM 6 PARES | H12: =IFERROR(VLOOKUP(Tabela4[[#This Row],[Cabo]],BD!A:V,3,0),"") -> - | I12: =IFERROR(VLOOKUP(Tabela4[[#This Row],[Cabo]],BD!A:V,4,0),"") -> - | J12: =IFERROR(VLOOKUP(Tabela4[[#This Row],[Cabo]],BD!A:V,7,0),"") -> 1 | K12: =IFERROR(IF(ROUNDDOWN(Tabela4[[#This Row],[%Lanç]]*Tabela4[[#This Row],[Lances Totais]],0)>Tabela4[[#This Row],[Lances Totais]],Tabela4[[#This Row],[Lances Totais]],ROUNDDOWN(Tabela4[[#This Row],[%Lanç]]*Tabela4[[#This Row],[Lances Totais]],0)),"") -> 1 | L12: =IFERROR(VLOOKUP(Tabela4[[#This Row],[Cabo]],BD!A:V,9,0),"") -> 125 | M12: =IFERROR(VLOOKUP(Tabela4[[#This Row],[Cabo]],BD!A:AD,30,0),"") -> 148 | N12: =IF(SUMIF('Lançamento de Cabos'!B:B,Tabela4[[#This Row],[Cabo]],'Lançamento de Cabos'!C:C)=0,"",SUMIF('Lançamento de Cabos'!B:B,Tabela4[[#This Row],[Cabo]],'Lançamento de Cabos'!C:C)) -> 148 | O12: =IFERROR(IF(Tabela4[[#This Row],[Compr. Lançado]]/Tabela4[[#This Row],[Compr. Prev.]]>1,1,Tabela4[[#This Row],[Compr. Lançado]]/Tabela4[[#This Row],[Compr. Prev.]]),"") -> 1 | P12: =IFERROR(VLOOKUP(Tabela4[[#This Row],[Cabo]],BD!A:V,11,0),"") -> RACK 7HV - RCK-120-102 | Q12: =IFERROR(VLOOKUP(Tabela4[[#This Row],[Cabo]],BD!A:V,12,0),"") -> RCK-120-103 - RACK 30LV | R12: =IF(Tabela4[[#This Row],[Cabo]]<>"",IFERROR(VLOOKUP(Tabela4[[#This Row],[Cabo]]&"-1",'Lançamento de Cabos'!$S:$T,2,0),IF(VLOOKUP(Tabela4[[#This Row],[Cabo]],BD!A:V,13,0)="---","---","")),"") -> --- | S12: =IF(Tabela4[[#This Row],[Cabo]]<>"",IFERROR(VLOOKUP(Tabela4[[#This Row],[Cabo]]&"-2",'Lançamento de Cabos'!$S:$T,2,0),IF(VLOOKUP(Tabela4[[#This Row],[Cabo]],BD!A:V,14,0)="---","---","")),"") -> --- | T12: =IF(Tabela4[[#This Row],[Cabo]]<>"",IFERROR(VLOOKUP(Tabela4[[#This Row],[Cabo]]&"-3",'Lançamento de Cabos'!$S:$T,2,0),IF(VLOOKUP(Tabela4[[#This Row],[Cabo]],BD!A:V,15,0)="---","---","")),"") -> --- | U12: =IF(Tabela4[[#This Row],[Cabo]]<>"",IFERROR(VLOOKUP(Tabela4[[#This Row],[Cabo]]&"-4",'Lançamento de Cabos'!$S:$T,2,0),IF(VLOOKUP(Tabela4[[#This Row],[Cabo]],BD!A:V,16,0)="---","---","")),"") -> --- | V12: =IF(Tabela4[[#This Row],[Cabo]]<>"",4-COUNTIF(Tabela4[[#This Row],[Teste de Continuidade]:[Hipot]],"---"),"") -> 0 | W12: =IF(Tabela4[[#This Row],[Cabo]]<>"",(COUNTIF(Tabela4[[#This Row],[Teste de Continuidade]:[Hipot]],"OK"))/(4-COUNTIF(Tabela4[[#This Row],[Teste de Continuidade]:[Hipot]],"---")),"") -> #DIV/0! | X12: =IF(Tabela4[[#This Row],[Cabo]]<>"",SUMIFS('Lançamento de Cabos'!$AF:$AF,'Lançamento de Cabos'!AE:AE,Tabela4[[#This Row],[Cabo]],'Lançamento de Cabos'!AJ:AJ,Área!$B$1),"") -> 0 | Y12: =IF(Tabela4[[#This Row],[Cabo]]<>"",SUMIFS('Lançamento de Cabos'!$AG:$AG,'Lançamento de Cabos'!AE:AE,Tabela4[[#This Row],[Cabo]],'Lançamento de Cabos'!AJ:AJ,Área!$B$1),"") -> 0 | Z12: =VLOOKUP(Tabela4[[#This Row],[Cabo]],BD!A:AB,28,0) -> Disponível
C13: =IF($B$1="Geral",Tabela1[[#This Row],[Tag do Cabo]],IFERROR(INDEX(INDIRECT("BD!$A"&D13&":$A100000"),E13,1),"")) -> CDC-12007 | D13: =IFERROR(D12+E12,"") -> 175 | E13: =IFERROR(MATCH($B$1,INDIRECT("BD!$J"&D13&":$J100000"),0),"") -> 31 | F13: =IFERROR(VLOOKUP(Tabela4[[#This Row],[Cabo]],BD!A:V,2,0),"") -> FO | G13: =IFERROR(VLOOKUP(Tabela4[[#This Row],[Cabo]],BD!A:V,5,0),"") -> FIBRA OPTICA SM 6 PARES | H13: =IFERROR(VLOOKUP(Tabela4[[#This Row],[Cabo]],BD!A:V,3,0),"") -> - | I13: =IFERROR(VLOOKUP(Tabela4[[#This Row],[Cabo]],BD!A:V,4,0),"") -> - | J13: =IFERROR(VLOOKUP(Tabela4[[#This Row],[Cabo]],BD!A:V,7,0),"") -> 1 | K13: =IFERROR(IF(ROUNDDOWN(Tabela4[[#This Row],[%Lanç]]*Tabela4[[#This Row],[Lances Totais]],0)>Tabela4[[#This Row],[Lances Totais]],Tabela4[[#This Row],[Lances Totais]],ROUNDDOWN(Tabela4[[#This Row],[%Lanç]]*Tabela4[[#This Row],[Lances Totais]],0)),"") -> 1 | L13: =IFERROR(VLOOKUP(Tabela4[[#This Row],[Cabo]],BD!A:V,9,0),"") -> 220 | M13: =IFERROR(VLOOKUP(Tabela4[[#This Row],[Cabo]],BD!A:AD,30,0),"") -> 350 | N13: =IF(SUMIF('Lançamento de Cabos'!B:B,Tabela4[[#This Row],[Cabo]],'Lançamento de Cabos'!C:C)=0,"",SUMIF('Lançamento de Cabos'!B:B,Tabela4[[#This Row],[Cabo]],'Lançamento de Cabos'!C:C)) -> 350 | O13: =IFERROR(IF(Tabela4[[#This Row],[Compr. Lançado]]/Tabela4[[#This Row],[Compr. Prev.]]>1,1,Tabela4[[#This Row],[Compr. Lançado]]/Tabela4[[#This Row],[Compr. Prev.]]),"") -> 1 | P13: =IFERROR(VLOOKUP(Tabela4[[#This Row],[Cabo]],BD!A:V,11,0),"") -> DIO-120-104 (RCK-120-102) / ELETROCENTRO MOTORIZAÇÃO | Q13: =IFERROR(VLOOKUP(Tabela4[[#This Row],[Cabo]],BD!A:V,12,0),"") -> DIO-CCP-104 (RCK-CCP-101) / CCP | R13: =IF(Tabela4[[#This Row],[Cabo]]<>"",IFERROR(VLOOKUP(Tabela4[[#This Row],[Cabo]]&"-1",'Lançamento de Cabos'!$S:$T,2,0),IF(VLOOKUP(Tabela4[[#This Row],[Cabo]],BD!A:V,13,0)="---","---","")),"") -> --- | S13: =IF(Tabela4[[#This Row],[Cabo]]<>"",IFERROR(VLOOKUP(Tabela4[[#This Row],[Cabo]]&"-2",'Lançamento de Cabos'!$S:$T,2,0),IF(VLOOKUP(Tabela4[[#This Row],[Cabo]],BD!A:V,14,0)="---","---","")),"") -> --- | T13: =IF(Tabela4[[#This Row],[Cabo]]<>"",IFERROR(VLOOKUP(Tabela4[[#This Row],[Cabo]]&"-3",'Lançamento de Cabos'!$S:$T,2,0),IF(VLOOKUP(Tabela4[[#This Row],[Cabo]],BD!A:V,15,0)="---","---","")),"") -> --- | U13: =IF(Tabela4[[#This Row],[Cabo]]<>"",IFERROR(VLOOKUP(Tabela4[[#This Row],[Cabo]]&"-4",'Lançamento de Cabos'!$S:$T,2,0),IF(VLOOKUP(Tabela4[[#This Row],[Cabo]],BD!A:V,16,0)="---","---","")),"") -> --- | V13: =IF(Tabela4[[#This Row],[Cabo]]<>"",4-COUNTIF(Tabela4[[#This Row],[Teste de Continuidade]:[Hipot]],"---"),"") -> 0 | W13: =IF(Tabela4[[#This Row],[Cabo]]<>"",(COUNTIF(Tabela4[[#This Row],[Teste de Continuidade]:[Hipot]],"OK"))/(4-COUNTIF(Tabela4[[#This Row],[Teste de Continuidade]:[Hipot]],"---")),"") -> #DIV/0! | X13: =IF(Tabela4[[#This Row],[Cabo]]<>"",SUMIFS('Lançamento de Cabos'!$AF:$AF,'Lançamento de Cabos'!AE:AE,Tabela4[[#This Row],[Cabo]],'Lançamento de Cabos'!AJ:AJ,Área!$B$1),"") -> 0 | Y13: =IF(Tabela4[[#This Row],[Cabo]]<>"",SUMIFS('Lançamento de Cabos'!$AG:$AG,'Lançamento de Cabos'!AE:AE,Tabela4[[#This Row],[Cabo]],'Lançamento de Cabos'!AJ:AJ,Área!$B$1),"") -> 0 | Z13: =VLOOKUP(Tabela4[[#This Row],[Cabo]],BD!A:AB,28,0) -> Disponível
C14: =IF($B$1="Geral",Tabela1[[#This Row],[Tag do Cabo]],IFERROR(INDEX(INDIRECT("BD!$A"&D14&":$A100000"),E14,1),"")) -> CDC-12010 | D14: =IFERROR(D13+E13,"") -> 206 | E14: =IFERROR(MATCH($B$1,INDIRECT("BD!$J"&D14&":$J100000"),0),"") -> 1 | F14: =IFERROR(VLOOKUP(Tabela4[[#This Row],[Cabo]],BD!A:V,2,0),"") -> FO | G14: =IFERROR(VLOOKUP(Tabela4[[#This Row],[Cabo]],BD!A:V,5,0),"") -> FIBRA OPTICA SM 6 PARES | H14: =IFERROR(VLOOKUP(Tabela4[[#This Row],[Cabo]],BD!A:V,3,0),"") -> - | I14: =IFERROR(VLOOKUP(Tabela4[[#This Row],[Cabo]],BD!A:V,4,0),"") -> - | J14: =IFERROR(VLOOKUP(Tabela4[[#This Row],[Cabo]],BD!A:V,7,0),"") -> 1 | K14: =IFERROR(IF(ROUNDDOWN(Tabela4[[#This Row],[%Lanç]]*Tabela4[[#This Row],[Lances Totais]],0)>Tabela4[[#This Row],[Lances Totais]],Tabela4[[#This Row],[Lances Totais]],ROUNDDOWN(Tabela4[[#This Row],[%Lanç]]*Tabela4[[#This Row],[Lances Totais]],0)),"") -> 1 | L14: =IFERROR(VLOOKUP(Tabela4[[#This Row],[Cabo]],BD!A:V,9,0),"") -> 350 | M14: =IFERROR(VLOOKUP(Tabela4[[#This Row],[Cabo]],BD!A:AD,30,0),"") -> 350 | N14: =IF(SUMIF('Lançamento de Cabos'!B:B,Tabela4[[#This Row],[Cabo]],'Lançamento de Cabos'!C:C)=0,"",SUMIF('Lançamento de Cabos'!B:B,Tabela4[[#This Row],[Cabo]],'Lançamento de Cabos'!C:C)) -> 350 | O14: =IFERROR(IF(Tabela4[[#This Row],[Compr. Lançado]]/Tabela4[[#This Row],[Compr. Prev.]]>1,1,Tabela4[[#This Row],[Compr. Lançado]]/Tabela4[[#This Row],[Compr. Prev.]]),"") -> 1 | P14: =IFERROR(VLOOKUP(Tabela4[[#This Row],[Cabo]],BD!A:V,11,0),"") -> RACK 7HV - RCK-120-102 | Q14: =IFERROR(VLOOKUP(Tabela4[[#This Row],[Cabo]],BD!A:V,12,0),"") -> RACK CCP - RCK-90-105 | R14: =IF(Tabela4[[#This Row],[Cabo]]<>"",IFERROR(VLOOKUP(Tabela4[[#This Row],[Cabo]]&"-1",'Lançamento de Cabos'!$S:$T,2,0),IF(VLOOKUP(Tabela4[[#This Row],[Cabo]],BD!A:V,13,0)="---","---","")),"") -> --- | S14: =IF(Tabela4[[#This Row],[Cabo]]<>"",IFERROR(VLOOKUP(Tabela4[[#This Row],[Cabo]]&"-2",'Lançamento de Cabos'!$S:$T,2,0),IF(VLOOKUP(Tabela4[[#This Row],[Cabo]],BD!A:V,14,0)="---","---","")),"") -> --- | T14: =IF(Tabela4[[#This Row],[Cabo]]<>"",IFERROR(VLOOKUP(Tabela4[[#This Row],[Cabo]]&"-3",'Lançamento de Cabos'!$S:$T,2,0),IF(VLOOKUP(Tabela4[[#This Row],[Cabo]],BD!A:V,15,0)="---","---","")),"") -> --- | U14: =IF(Tabela4[[#This Row],[Cabo]]<>"",IFERROR(VLOOKUP(Tabela4[[#This Row],[Cabo]]&"-4",'Lançamento de Cabos'!$S:$T,2,0),IF(VLOOKUP(Tabela4[[#This Row],[Cabo]],BD!A:V,16,0)="---","---","")),"") -> --- | V14: =IF(Tabela4[[#This Row],[Cabo]]<>"",4-COUNTIF(Tabela4[[#This Row],[Teste de Continuidade]:[Hipot]],"---"),"") -> 0 | W14: =IF(Tabela4[[#This Row],[Cabo]]<>"",(COUNTIF(Tabela4[[#This Row],[Teste de Continuidade]:[Hipot]],"OK"))/(4-COUNTIF(Tabela4[[#This Row],[Teste de Continuidade]:[Hipot]],"---")),"") -> #DIV/0! | X14: =IF(Tabela4[[#This Row],[Cabo]]<>"",SUMIFS('Lançamento de Cabos'!$AF:$AF,'Lançamento de Cabos'!AE:AE,Tabela4[[#This Row],[Cabo]],'Lançamento de Cabos'!AJ:AJ,Área!$B$1),"") -> 0 | Y14: =IF(Tabela4[[#This Row],[Cabo]]<>"",SUMIFS('Lançamento de Cabos'!$AG:$AG,'Lançamento de Cabos'!AE:AE,Tabela4[[#This Row],[Cabo]],'Lançamento de Cabos'!AJ:AJ,Área!$B$1),"") -> 0 | Z14: =VLOOKUP(Tabela4[[#This Row],[Cabo]],BD!A:AB,28,0) -> Disponível
... C575: =IF($B$1="Geral",Tabela1[[#This Row],[Tag do Cabo]],IFERROR(INDEX(INDIRECT("BD!$A"&D575&":$A100000"),E575,1),"")) | D575: =IFERROR(D574+E574,"") | E575: =IFERROR(MATCH($B$1,INDIRECT("BD!$J"&D575&":$J100000"),0),"") | F575: =IFERROR(VLOOKUP(Tabela4[[#This Row],[Cabo]],BD!A:V,2,0),"") | G575: =IFERROR(VLOOKUP(Tabela4[[#This Row],[Cabo]],BD!A:V,5,0),"") | H575: =IFERROR(VLOOKUP(Tabela4[[#This Row],[Cabo]],BD!A:V,3,0),"") | I575: =IFERROR(VLOOKUP(Tabela4[[#This Row],[Cabo]],BD!A:V,4,0),"") | J575: =IFERROR(VLOOKUP(Tabela4[[#This Row],[Cabo]],BD!A:V,7,0),"") | K575: =IFERROR(IF(ROUNDDOWN(Tabela4[[#This Row],[%Lanç]]*Tabela4[[#This Row],[Lances Totais]],0)>Tabela4[[#This Row],[Lances Totais]],Tabela4[[#This Row],[Lances Totais]],ROUNDDOWN(Tabela4[[#This Row],[%Lanç]]*Tabela4[[#This Row],[Lances Totais]],0)),"") | L575: =IFERROR(VLOOKUP(Tabela4[[#This Row],[Cabo]],BD!A:V,9,0),"") | M575: =IFERROR(VLOOKUP(Tabela4[[#This Row],[Cabo]],BD!A:AD,30,0),"") | N575: =IF(SUMIF('Lançamento de Cabos'!B:B,Tabela4[[#This Row],[Cabo]],'Lançamento de Cabos'!C:C)=0,"",SUMIF('Lançamento de Cabos'!B:B,Tabela4[[#This Row],[Cabo]],'Lançamento de Cabos'!C:C)) | O575: =IFERROR(IF(Tabela4[[#This Row],[Compr. Lançado]]/Tabela4[[#This Row],[Compr. Prev.]]>1,1,Tabela4[[#This Row],[Compr. Lançado]]/Tabela4[[#This Row],[Compr. Prev.]]),"") | P575: =IFERROR(VLOOKUP(Tabela4[[#This Row],[Cabo]],BD!A:V,11,0),"") | Q575: =IFERROR(VLOOKUP(Tabela4[[#This Row],[Cabo]],BD!A:V,12,0),"") | R575: =IF(Tabela4[[#This Row],[Cabo]]<>"",IFERROR(VLOOKUP(Tabela4[[#This Row],[Cabo]]&"-1",'Lançamento de Cabos'!$S:$T,2,0),IF(VLOOKUP(Tabela4[[#This Row],[Cabo]],BD!A:V,13,0)="---","---","")),"") | S575: =IF(Tabela4[[#This Row],[Cabo]]<>"",IFERROR(VLOOKUP(Tabela4[[#This Row],[Cabo]]&"-2",'Lançamento de Cabos'!$S:$T,2,0),IF(VLOOKUP(Tabela4[[#This Row],[Cabo]],BD!A:V,14,0)="---","---","")),"") | T575: =IF(Tabela4[[#This Row],[Cabo]]<>"",IFERROR(VLOOKUP(Tabela4[[#This Row],[Cabo]]&"-3",'Lançamento de Cabos'!$S:$T,2,0),IF(VLOOKUP(Tabela4[[#This Row],[Cabo]],BD!A:V,15,0)="---","---","")),"") | U575: =IF(Tabela4[[#This Row],[Cabo]]<>"",IFERROR(VLOOKUP(Tabela4[[#This Row],[Cabo]]&"-4",'Lançamento de Cabos'!$S:$T,2,0),IF(VLOOKUP(Tabela4[[#This Row],[Cabo]],BD!A:V,16,0)="---","---","")),"") | V575: =IF(Tabela4[[#This Row],[Cabo]]<>"",4-COUNTIF(Tabela4[[#This Row],[Teste de Continuidade]:[Hipot]],"---"),"") | W575: =IF(Tabela4[[#This Row],[Cabo]]<>"",(COUNTIF(Tabela4[[#This Row],[Teste de Continuidade]:[Hipot]],"OK"))/(4-COUNTIF(Tabela4[[#This Row],[Teste de Continuidade]:[Hipot]],"---")),"") | X575: =IF(Tabela4[[#This Row],[Cabo]]<>"",SUMIFS('Lançamento de Cabos'!$AF:$AF,'Lançamento de Cabos'!AE:AE,Tabela4[[#This Row],[Cabo]],'Lançamento de Cabos'!AJ:AJ,Área!$B$1),"") | Y575: =IF(Tabela4[[#This Row],[Cabo]]<>"",SUMIFS('Lançamento de Cabos'!$AG:$AG,'Lançamento de Cabos'!AE:AE,Tabela4[[#This Row],[Cabo]],'Lançamento de Cabos'!AJ:AJ,Área!$B$1),"") | Z575: =VLOOKUP(Tabela4[[#This Row],[Cabo]],BD!A:AB,28,0) -> #N/A

Sheet Dashboard
H1: Lançamento de Cabos - Projeto Vesta
B6: Lançamento de Cabos - Geral | R6: Selecionar Área: | V6: FIBRA | AH6: ESCOPO - Listas de Cabos
R7: ="Lançamento de Cabos - Área - "&V6 -> Lançamento de Cabos - Área - FIBRA | AH7: Lista de Cabos | AO7: Total (m) | AQ7: Lançado (m) | AS7: %
B8: =Indicadores!M7 -> 0.90391169 | F8: Tipo | H8: Qtde Total | J8: Qtde Lançada | L8: % | N8: Saldo | R8: =Indicadores!M15 -> 0.75380898 | V8: Tipo | X8: Qtde Total | Z8: Qtde Lançada | AB8: % | AD8: Saldo | AH8: =CONCATENATE(Indicadores!A10,"-Rev.",Indicadores!B10) -> BK-SP54-00200-LC-80-00699_00000-Rev.2 | AO8: =Indicadores!C10 -> 230 | AQ8: =Indicadores!D10 -> 230 | AS8: =Indicadores!E10 -> 1
F9: Força | H9: =Indicadores!K3 -> 52918 | J9: =Indicadores!L3 -> 49068 | L9: =Indicadores!M3 -> 0.92724593 | N9: =Indicadores!N3 -> 3850 | V9: Força | X9: =IF($V$6="Geral",Indicadores!K3,Indicadores!K11) -> 0 | Z9: =IF($V$6="Geral",Indicadores!L3,Indicadores!L11) -> 0 | AB9: =IF($V$6="Geral",Indicadores!M3,Indicadores!M11) -> 0 | AD9: =IF($V$6="Geral",Indicadores!N3,Indicadores!N11) -> 0 | AH9: =CONCATENATE(Indicadores!A11,"-Rev.",Indicadores!B11) -> BK-SP54-00200-LC-81-00001_00000-Rev.6 | AO9: =Indicadores!C11 -> 5510 | AQ9: =Indicadores!D11 -> 5510 | AS9: =Indicadores!E11 -> 1
AH10: =CONCATENATE(Indicadores!A12,"-Rev.",Indicadores!B12) -> BK-SP54-00350-LC-80-00006_00000-Rev.6 | AO10: =Indicadores!C12 -> 6698 | AQ10: =Indicadores!D12 -> 6698 | AS10: =Indicadores!E12 -> 1
F11: Controle | H11: =Indicadores!K4 -> 37825 | J11: =Indicadores!L4 -> 34991 | L11: =Indicadores!M4 -> 0.92507601 | N11: =Indicadores!N4 -> 2834 | V11: Controle | X11: =IF($V$6="Geral",Indicadores!K4,Indicadores!K12) -> 0 | Z11: =IF($V$6="Geral",Indicadores!L4,Indicadores!L12) -> 0 | AB11: =IF($V$6="Geral",Indicadores!M4,Indicadores!M12) -> 0 | AD11: =IF($V$6="Geral",Indicadores!N4,Indicadores!N12) -> 0 | AH11: =CONCATENATE(Indicadores!A13,"-Rev.",Indicadores!B13) -> BK-SP54-00350-LC-80-00059_00000-Rev.2 | AO11: =Indicadores!C13 -> 100 | AQ11: =Indicadores!D13 -> 0 | AS11: =Indicadores!E13 -> 0
AH12: =CONCATENATE(Indicadores!A14,"-Rev.",Indicadores!B14) -> BK-SP54-01200-LC-80-00004_00000-Rev.10 | AO12: =Indicadores!C14 -> 5996 | AQ12: =Indicadores!D14 -> 5996 | AS12: =Indicadores!E14 -> 1
F13: Fibra Ótica | H13: =Indicadores!K5 -> 12208 | J13: =Indicadores!L5 -> 9202.5 | L13: =Indicadores!M5 -> 0.75380898 | N13: =Indicadores!N5 -> 3005.5 | V13: Fibra Ótica | X13: =IF($V$6="Geral",Indicadores!K5,Indicadores!K13) -> 12208 | Z13: =IF($V$6="Geral",Indicadores!L5,Indicadores!L13) -> 9202.5 | AB13: =IF($V$6="Geral",Indicadores!M5,Indicadores!M13) -> 0.75380898 | AD13: =IF($V$6="Geral",Indicadores!N5,Indicadores!N13) -> 3005.5 | AH13: =CONCATENATE(Indicadores!A15,"-Rev.",Indicadores!B15) -> BK-SP54-0900A-LC-74-00001_00000-Rev.5 | AO13: =Indicadores!C15 -> 58185 | AQ13: =Indicadores!D15 -> 50577 | AS13: =Indicadores!E15 -> 0.86924465
AH14: =CONCATENATE(Indicadores!A16,"-Rev.",Indicadores!B16) -> BK-SP54-0900A-LC-80-00168_00000-Rev.7 | AO14: =Indicadores!C16 -> 20 | AQ14: =Indicadores!D16 -> 0 | AS14: =Indicadores!E16 -> 0
F15: Rede | H15: =Indicadores!K6 -> 776.5 | J15: =Indicadores!L6 -> 499 | L15: =Indicadores!M6 -> 0.64262717 | N15: =Indicadores!N6 -> 277.5 | V15: Rede | X15: =IF($V$6="Geral",Indicadores!K6,Indicadores!K14) -> 0 | Z15: =IF($V$6="Geral",Indicadores!L6,Indicadores!L14) -> 0 | AB15: =IF($V$6="Geral",Indicadores!M6,Indicadores!M14) -> 0 | AD15: =IF($V$6="Geral",Indicadores!N6,Indicadores!N14) -> 0 | AH15: =CONCATENATE(Indicadores!A17,"-Rev.",Indicadores!B17) -> BK-SP54-0900A-LC-80-00177_00000-Rev.4 | AO15: =Indicadores!C17 -> 20 | AQ15: =Indicadores!D17 -> 0 | AS15: =Indicadores!E17 -> 0
AH16: =CONCATENATE(Indicadores!A18,"-Rev.",Indicadores!B18) -> BK-SP54-0900A-LC-80-00178_00000-Rev.3 | AO16: =Indicadores!C18 -> 25 | AQ16: =Indicadores!D18 -> 0 | AS16: =Indicadores!E18 -> 0
F17: Geral | H17: =Indicadores!K7 -> 103727.5 | J17: =Indicadores!L7 -> 93760.5 | L17: =Indicadores!M7 -> 0.90391169 | N17: =Indicadores!N7 -> 9967 | V17: Geral | X17: =IF(V6="Geral",Indicadores!K7,Indicadores!K15) -> 12208 | Z17: =IF($V$6="Geral",Indicadores!L7,Indicadores!L15) -> 9202.5 | AB17: =IF($V$6="Geral",Indicadores!M7,Indicadores!M15) -> 0.75380898 | AD17: =IF($V$6="Geral",Indicadores!N7,Indicadores!N15) -> 3005.5 | AH17: =CONCATENATE(Indicadores!A19,"-Rev.",Indicadores!B19) -> BK-SP54-0900A-LC-80-00179_00000-Rev.4 | AO17: =Indicadores!C19 -> 22 | AQ17: =Indicadores!D19 -> 0 | AS17: =Indicadores!E19 -> 0
AH18: =CONCATENATE(Indicadores!A20,"-Rev.",Indicadores!B20) -> BK-SP54-0900A-LC-80-00180_00000-Rev.4 | AO18: =Indicadores!C20 -> 22 | AQ18: =Indicadores!D20 -> 0 | AS18: =Indicadores!E20 -> 0
AH19: =CONCATENATE(Indicadores!A21,"-Rev.",Indicadores!B21) -> BK-SP54-0900A-LC-80-00185_00000-Rev.2 | AO19: =Indicadores!C21 -> 470 | AQ19: =Indicadores!D21 -> 470 | AS19: =Indicadores!E21 -> 1
B20: Lançamento de Cabos - Aterramento | R20: ="Testes e Ligações - "&V6 -> Testes e Ligações - FIBRA | AH20: =CONCATENATE(Indicadores!A22,"-Rev.",Indicadores!B22) -> BK-SP54-0900A-LC-80-00186_00000-Rev.3 | AO20: =Indicadores!C22 -> 1607 | AQ20: =Indicadores!D22 -> 1502 | AS20: =Indicadores!E22 -> 0.93466086
AH21: =CONCATENATE(Indicadores!A23,"-Rev.",Indicadores!B23) -> BK-SP54-0900A-LC-80-00187_00000-Rev.2 | AO21: =Indicadores!C23 -> 1320 | AQ21: =Indicadores!D23 -> 1120 | AS21: =Indicadores!E23 -> 0.84848485
B22: =L27 -> 0.88364865 | F22: Tipo | H22: Qtde Total | J22: Qtde Lançada | L22: % | N22: Saldo | R22: Avanço | V22: Tipo | X22: Total | Z22: Realizado | AB22: % | AD22: Saldo | AH22: =CONCATENATE(Indicadores!A24,"-Rev.",Indicadores!B24) -> BK-SP54-0900A-LC-80-00188_00000-Rev.2 | AO22: =Indicadores!C24 -> 3248 | AQ22: =Indicadores!D24 -> 2958 | AS22: =Indicadores!E24 -> 0.91071429
F23: 70 mm² 19 Fios | H23: =Indicadores!K18 -> 5700 | J23: =Indicadores!L18 -> 5239 | L23: =Indicadores!M18 -> 0.50755668 | N23: =Indicadores!N18 -> 461 | V23: Teste Cont. | X23: =Indicadores!K23 -> 7 | Z23: =Indicadores!L23 -> 0 | AB23: =Indicadores!M23 -> 0 | AD23: =Indicadores!N23 -> 7 | AH23: =CONCATENATE(Indicadores!A25,"-Rev.",Indicadores!B25) -> BK-SP54-0900A-LC-90-00004_00000-Rev.2 | AO23: =Indicadores!C25 -> 2959.5 | AQ23: =Indicadores!D25 -> 1669.5 | AS23: =Indicadores!E25 -> 0.56411556
V24: Born a Born | X24: =Indicadores!K24 -> 7 | Z24: =Indicadores!L24 -> 0 | AB24: =Indicadores!M24 -> 0 | AD24: =Indicadores!N24 -> 7 | AH24: =CONCATENATE(Indicadores!A26,"-Rev.",Indicadores!B26) -> BK-SP54-0900B-LC-74-00004_00000-Rev.2 | AO24: =Indicadores!C26 -> 12895 | AQ24: =Indicadores!D26 -> 12895 | AS24: =Indicadores!E26 -> 1
F25: 25 mm² 7 Fios | H25: =Indicadores!K19 -> 1700 | J25: =Indicadores!L19 -> 1300 | L25: =Indicadores!M19 -> 0.76470588 | N25: =Indicadores!N19 -> 400 | V25: Megger | X25: =Indicadores!K25 -> 0 | Z25: =Indicadores!L25 -> 0 | AB25: =Indicadores!M25 -> 0 | AD25: =Indicadores!N25 -> 0 | AH25: =CONCATENATE(Indicadores!A27,"-Rev.",Indicadores!B27) -> BK-SP54-0900B-LC-80-00155_00000-Rev.2 | AO25: =Indicadores!C27 -> 1250 | AQ25: =Indicadores!D27 -> 1000 | AS25: =Indicadores!E27 -> 0.8
V26: Hipot | X26: =Indicadores!K26 -> 0 | Z26: =Indicadores!L26 -> 0 | AB26: =Indicadores!M26 -> 0 | AD26: =Indicadores!N26 -> 0 | AH26: =CONCATENATE(Indicadores!A28,"-Rev.",Indicadores!B28) -> BK-SP54-0900B-LC-90-00010_00000-Rev.1 | AO26: =Indicadores!C28 -> 879 | AQ26: =Indicadores!D28 -> 864 | AS26: =Indicadores!E28 -> 0.98293515
F27: Geral | H27: =Indicadores!K20 -> 7400 | J27: =Indicadores!L20 -> 6539 | L27: =Indicadores!M20 -> 0.88364865 | N27: =Indicadores!N20 -> 861 | V27: Ligações | X27: =Indicadores!K27 -> 218 | Z27: =Indicadores!L27 -> 36 | AB27: =Indicadores!M27 -> 0.16513761 | AD27: =Indicadores!N27 -> 182 | AH27: =CONCATENATE(Indicadores!A29,"-Rev.",Indicadores!B29) -> E5WP000490-C-001-LC003-Rev.2 | AO27: =Indicadores!C29 -> 1949 | AQ27: =Indicadores!D29 -> 1949 | AS27: =Indicadores!E29 -> 1
AH28: =CONCATENATE(Indicadores!A30,"-Rev.",Indicadores!B30) -> E5WP000490-C-001-LC004-Rev.2 | AO28: =Indicadores!C30 -> 322 | AQ28: =Indicadores!D30 -> 322 | AS28: =Indicadores!E30 -> 1
AH29: Total | AO29: =SUM(AO7:AP28) -> 103727.5 | AQ29: =SUM(AQ7:AR28) -> 93760.5 | AS29: =AQ29/AO29 -> 0.90391169
B31: ="Acompanhamento - Lançamento de Cabos - "&V6 -> Acompanhamento - Lançamento de Cabos - FIBRA
C54: =IF($V$6="Geral","Status Geral de Cabos","Status Geral de Cabos - Área - "&$V$6) -> Status Geral de Cabos - Área - FIBRA
C55: Circuito | G55: Tipo | I55: Formação | K55: Tensão | M55: Isolamento | O55: Lances Totais | Q55: Lances Realizados | S55: Compr. Total | U55: Compr. Lançado | W55: Compr. Real | Y55: % Lanç | Z55: DE | AD55: PARA | AH55: Teste Cont. | AJ55: Born a Born | AL55: Megger | AN55: Hipot | AP55: Status Liberação | AR55: Ligações Realizadas
C56: =Área!C2 -> 1HVBUS3-ER1HV-001C | G56: =Área!F2 -> FO | I56: =Área!G2 -> CORDÃO ÓPTICO | K56: =Área!H2 -> - | M56: =Área!I2 -> - | O56: =Área!J2 -> 1 | Q56: =Área!K2 -> 1 | S56: =Área!L2 -> 40 | U56: =Área!N2 -> 40 | W56: =Área!M2 -> 40 | Y56: =Área!O2 -> 1 | Z56: =Área!P2 -> 1HV-BUS3 | AD56: =Área!Q2 -> ER-3 | AH56: =Área!R2 -> --- | AJ56: =Área!S2 -> --- | AL56: =Área!T2 -> --- | AN56: =Área!U2 -> --- | AP56: =IFERROR(Área!Z2,"") -> Disponível | AR56: =Área!Y2 -> 0
C57: =Área!C3 -> 1HVBUS3-ER1HV-002C | G57: =Área!F3 -> FO | I57: =Área!G3 -> CORDÃO ÓPTICO | K57: =Área!H3 -> - | M57: =Área!I3 -> - | O57: =Área!J3 -> 1 | Q57: =Área!K3 -> 1 | S57: =Área!L3 -> 40 | U57: =Área!N3 -> 40 | W57: =Área!M3 -> 40 | Y57: =Área!O3 -> 1 | Z57: =Área!P3 -> 1HV-BUS3 | AD57: =Área!Q3 -> ER-3 | AH57: =Área!R3 -> --- | AJ57: =Área!S3 -> --- | AL57: =Área!T3 -> --- | AN57: =Área!U3 -> --- | AP57: =IFERROR(Área!Z3,"") -> Disponível | AR57: =Área!Y3 -> 0
C58: =Área!C4 -> 1HVBUS3-ER1HV-003C | G58: =Área!F4 -> FO | I58: =Área!G4 -> CORDÃO ÓPTICO | K58: =Área!H4 -> - | M58: =Área!I4 -> - | O58: =Área!J4 -> 1 | Q58: =Área!K4 -> 1 | S58: =Área!L4 -> 40 | U58: =Área!N4 -> 40 | W58: =Área!M4 -> 40 | Y58: =Área!O4 -> 1 | Z58: =Área!P4 -> 1HV-BUS3 | AD58: =Área!Q4 -> ER-3 | AH58: =Área!R4 -> --- | AJ58: =Área!S4 -> --- | AL58: =Área!T4 -> --- | AN58: =Área!U4 -> --- | AP58: =IFERROR(Área!Z4,"") -> Disponível | AR58: =Área!Y4 -> 0
C59: =Área!C5 -> 1HVBUS3-ER1HV-004C | G59: =Área!F5 -> FO | I59: =Área!G5 -> CORDÃO ÓPTICO | K59: =Área!H5 -> - | M59: =Área!I5 -> - | O59: =Área!J5 -> 1 | Q59: =Área!K5 -> 1 | S59: =Área!L5 -> 40 | U59: =Área!N5 -> 40 | W59: =Área!M5 -> 40 | Y59: =Área!O5 -> 1 | Z59: =Área!P5 -> 1HV-BUS3 | AD59: =Área!Q5 -> ER-3 | AH59: =Área!R5 -> --- | AJ59: =Área!S5 -> --- | AL59: =Área!T5 -> --- | AN59: =Área!U5 -> --- | AP59: =IFERROR(Área!Z5,"") -> Disponível | AR59: =Área!Y5 -> 0
C60: =Área!C6 -> 1HVBUS3-ER1HV-005C | G60: =Área!F6 -> FO | I60: =Área!G6 -> CORDÃO ÓPTICO | K60: =Área!H6 -> - | M60: =Área!I6 -> - | O60: =Área!J6 -> 1 | Q60: =Área!K6 -> 1 | S60: =Área!L6 -> 40 | U60: =Área!N6 -> 40 | W60: =Área!M6 -> 40 | Y60: =Área!O6 -> 1 | Z60: =Área!P6 -> 1HV-BUS3 | AD60: =Área!Q6 -> ER-3 | AH60: =Área!R6 -> --- | AJ60: =Área!S6 -> --- | AL60: =Área!T6 -> --- | AN60: =Área!U6 -> --- | AP60: =IFERROR(Área!Z6,"") -> Disponível | AR60: =Área!Y6 -> 0
C61: =Área!C7 -> CBO001-SEL | G61: =Área!F7 -> FO | I61: =Área!G7 -> CORDÃO ÓPTICO | K61: =Área!H7 -> - | M61: =Área!I7 -> - | O61: =Área!J7 -> 1 | Q61: =Área!K7 | S61: =Área!L7 -> 20 | U61: =Área!N7 | W61: =Área!M7 -> 20 | Y61: =Área!O7 | Z61: =Área!P7 -> ER-3 | AD61: =Área!Q7 -> ER-4 | AH61: =Área!R7 -> --- | AJ61: =Área!S7 -> --- | AL61: =Área!T7 -> --- | AN61: =Área!U7 -> --- | AP61: =IFERROR(Área!Z7,"") -> Pend. Compra | AR61: =Área!Y7 -> 0
C62: =Área!C8 -> CDC-02290 | G62: =Área!F8 -> FO | I62: =Área!G8 -> CORDÃO ÓPTICO | K62: =Área!H8 -> - | M62: =Área!I8 -> - | O62: =Área!J8 -> 1 | Q62: =Área!K8 -> 1 | S62: =Área!L8 -> 2.5 | U62: =Área!N8 -> 2.5 | W62: =Área!M8 -> 2.5 | Y62: =Área!O8 -> 1 | Z62: =Área!P8 -> DIO-120-104 (30LV) | AD62: =Área!Q8 -> SWT-120-105 (30LV) | AH62: =Área!R8 -> --- | AJ62: =Área!S8 -> --- | AL62: =Área!T8 -> --- | AN62: =Área!U8 -> --- | AP62: =IFERROR(Área!Z8,"") -> Disponível | AR62: =Área!Y8 -> 0
C63: =Área!C9 -> CDC-02331 | G63: =Área!F9 -> FO | I63: =Área!G9 -> CORDÃO ÓPTICO | K63: =Área!H9 -> - | M63: =Área!I9 -> - | O63: =Área!J9 -> 1 | Q63: =Área!K9 -> 1 | S63: =Área!L9 -> 5 | U63: =Área!N9 -> 5 | W63: =Área!M9 -> 5 | Y63: =Área!O9 -> 1 | Z63: =Área!P9 -> PI-1205 (ACESSO REMOTO) | AD63: =Área!Q9 -> SWT-120-105 (30LV) | AH63: =Área!R9 -> --- | AJ63: =Área!S9 -> --- | AL63: =Área!T9 -> --- | AN63: =Área!U9 -> --- | AP63: =IFERROR(Área!Z9,"") -> Disponível | AR63: =Área!Y9 -> 0
C64: =Área!C10 -> 7HV-1HV-001C | G64: =Área!F10 -> FO | I64: =Área!G10 -> CABO ÓPTICO 4 VIAS | K64: =Área!H10 -> - | M64: =Área!I10 -> - | O64: =Área!J10 -> 1 | Q64: =Área!K10 -> 1 | S64: =Área!L10 -> 450 | U64: =Área!N10 -> 450 | W64: =Área!M10 -> 450 | Y64: =Área!O10 -> 1 | Z64: =Área!P10 -> 7HV | AD64: =Área!Q10 -> REMOTA 1HV | AH64: =Área!R10 -> --- | AJ64: =Área!S10 -> --- | AL64: =Área!T10 -> --- | AN64: =Área!U10 -> --- | AP64: =IFERROR(Área!Z10,"") -> Disponível | AR64: =Área!Y10 -> 0
C65: =Área!C11 -> CBO005-RS | G65: =Área!F11 -> FO | I65: =Área!G11 -> CABO ÓPTICO 4 VIAS | K65: =Área!H11 -> - | M65: =Área!I11 -> - | O65: =Área!J11 -> 1 | Q65: =Área!K11 -> 1 | S65: =Área!L11 -> 450 | U65: =Área!N11 -> 450 | W65: =Área!M11 -> 450 | Y65: =Área!O11 -> 1 | Z65: =Área!P11 -> PSDC2-DIO | AD65: =Área!Q11 -> PSDC4-DIO1 | AH65: =Área!R11 -> --- | AJ65: =Área!S11 -> --- | AL65: =Área!T11 -> --- | AN65: =Área!U11 -> --- | AP65: =IFERROR(Área!Z11,"") -> Disponível | AR65: =Área!Y11 -> 8
C66: =Área!C12 -> CDC-12009 | G66: =Área!F12 -> FO | I66: =Área!G12 -> FIBRA OPTICA SM 6 PARES | K66: =Área!H12 -> - | M66: =Área!I12 -> - | O66: =Área!J12 -> 1 | Q66: =Área!K12 -> 1 | S66: =Área!L12 -> 125 | U66: =Área!N12 -> 148 | W66: =Área!M12 -> 148 | Y66: =Área!O12 -> 1 | Z66: =Área!P12 -> RACK 7HV - RCK-120-102 | AD66: =Área!Q12 -> RCK-120-103 - RACK 30LV | AH66: =Área!R12 -> --- | AJ66: =Área!S12 -> --- | AL66: =Área!T12 -> --- | AN66: =Área!U12 -> --- | AP66: =IFERROR(Área!Z12,"") -> Disponível | AR66: =Área!Y12 -> 0
C67: =Área!C13 -> CDC-12007 | G67: =Área!F13 -> FO | I67: =Área!G13 -> FIBRA OPTICA SM 6 PARES | K67: =Área!H13 -> - | M67: =Área!I13 -> - | O67: =Área!J13 -> 1 | Q67: =Área!K13 -> 1 | S67: =Área!L13 -> 220 | U67: =Área!N13 -> 350 | W67: =Área!M13 -> 350 | Y67: =Área!O13 -> 1 | Z67: =Área!P13 -> DIO-120-104 (RCK-120-102) / ELETROCENTRO MOTORIZAÇÃO | AD67: =Área!Q13 -> DIO-CCP-104 (RCK-CCP-101) / CCP | AH67: =Área!R13 -> --- | AJ67: =Área!S13 -> --- | AL67: =Área!T13 -> --- | AN67: =Área!U13 -> --- | AP67: =IFERROR(Área!Z13,"") -> Disponível | AR67: =Área!Y13 -> 0
...

Sheet BD
A1: Tag do Cabo | B1: Tipo | C1: Tensão do Circuito | D1: Classe Isolamento | E1: Formação | F1: Bitola (mm²) | G1: Qtd de Lances | H1: Comprimento Lance | I1: Comprimento Total | J1: Local para Curva de Acomp. | K1: DE | L1: PARA | M1: Teste de Continuidade | N1: Born a Born | O1: Megger | P1: Hipot | Q1: Item Medição | R1: Qtde. Lançada | S1: Qtde Ligações | T1: Lista de Cabos | U1: Revisão | V1: Luvas/Anilhas | W1: ID_Atividade | X1: Data de Solcitação do Cabo | Y1: Data de Liberação dos Cabos | Z1: Histórico | AA1: Bobina | AB1: Disponibilidade | AC1: Programação | AD1: Comprimento Real | AE1: Sinal | AF1: Circuito | AG1: Ligações Realizadas | AH1: %Ligações | AI1: Diagrama de Ligação | AJ1: Folha DI | AK1: NE | AL1: OBS
